Workbook

Sheet Stocks
A1: reference/note | B1: S_tot from Pauliuk et al. 2013 10.1016/j.resconrec.2012.11.008 2 datasets, one for pre 1900 one for 1900-2008 | C1: using stock split from Pauliuk (2013) for 1900-2008. Keeping stock split constant before 1900
B2: Stocks [kt]
A3: year | B3: total stock S | C3: S - Vehicles | D3: S - Machinery | E3: S - BC | F3: S - Appliances
A4: 1700 | B4: 4.5998179 | C4: =$B4*'Parameters (t)'!$B$103 -> 0.82497973 | D4: =$B4*'Parameters (t)'!$C$103 -> 0.63025432 | E4: =$B4*'Parameters (t)'!$D$103 -> 2.781957 | F4: =$B4*'Parameters (t)'!$E$103 -> 0.36262683
A5: 1701 | B5: 10.037147 | C5: =$B5*'Parameters (t)'!$B$103 -> 1.8001676 | D5: =$B5*'Parameters (t)'!$C$103 -> 1.3752621 | E5: =$B5*'Parameters (t)'!$D$103 -> 6.0704386 | F5: =$B5*'Parameters (t)'!$E$103 -> 0.7912789
A6: 1702 | B6: 16.311988 | C6: =$B6*'Parameters (t)'!$B$103 -> 2.9255635 | D6: =$B6*'Parameters (t)'!$C$103 -> 2.2350234 | E6: =$B6*'Parameters (t)'!$D$103 -> 9.8654448 | F6: =$B6*'Parameters (t)'!$E$103 -> 1.2859562
A7: 1703 | B7: 23.42434 | C7: =$B7*'Parameters (t)'!$B$103 -> 4.2011675 | D7: =$B7*'Parameters (t)'!$C$103 -> 3.2095382 | E7: =$B7*'Parameters (t)'!$D$103 -> 14.166975 | F7: =$B7*'Parameters (t)'!$E$103 -> 1.8466588
A8: 1704 | B8: 31.374203 | C8: =$B8*'Parameters (t)'!$B$103 -> 5.6269796 | D8: =$B8*'Parameters (t)'!$C$103 -> 4.2988065 | E8: =$B8*'Parameters (t)'!$D$103 -> 18.975031 | F8: =$B8*'Parameters (t)'!$E$103 -> 2.4733866
A9: 1705 | B9: 40.161578 | C9: =$B9*'Parameters (t)'!$B$103 -> 7.2029999 | D9: =$B9*'Parameters (t)'!$C$103 -> 5.5028283 | E9: =$B9*'Parameters (t)'!$D$103 -> 24.28961 | F9: =$B9*'Parameters (t)'!$E$103 -> 3.1661396
A10: 1706 | B10: 49.786464 | C10: =$B10*'Parameters (t)'!$B$103 -> 8.9292282 | D10: =$B10*'Parameters (t)'!$C$103 -> 6.8216036 | E10: =$B10*'Parameters (t)'!$D$103 -> 30.110715 | F10: =$B10*'Parameters (t)'!$E$103 -> 3.9249179
A11: 1707 | B11: 60.248862 | C11: =$B11*'Parameters (t)'!$B$103 -> 10.805665 | D11: =$B11*'Parameters (t)'!$C$103 -> 8.2551324 | E11: =$B11*'Parameters (t)'!$D$103 -> 36.438344 | F11: =$B11*'Parameters (t)'!$E$103 -> 4.7497214
A12: 1708 | B12: 71.548771 | C12: =$B12*'Parameters (t)'!$B$103 -> 12.832309 | D12: =$B12*'Parameters (t)'!$C$103 -> 9.8034146 | E12: =$B12*'Parameters (t)'!$D$103 -> 43.272497 | F12: =$B12*'Parameters (t)'!$E$103 -> 5.6405502
A13: 1709 | B13: 83.686191 | C13: =$B13*'Parameters (t)'!$B$103 -> 15.009162 | D13: =$B13*'Parameters (t)'!$C$103 -> 11.46645 | E13: =$B13*'Parameters (t)'!$D$103 -> 50.613175 | F13: =$B13*'Parameters (t)'!$E$103 -> 6.5974042
A14: 1710 | B14: 96.661123 | C14: =$B14*'Parameters (t)'!$B$103 -> 17.336222 | D14: =$B14*'Parameters (t)'!$C$103 -> 13.24424 | E14: =$B14*'Parameters (t)'!$D$103 -> 58.460377 | F14: =$B14*'Parameters (t)'!$E$103 -> 7.6202834
A15: 1711 | B15: 110.47357 | C15: =$B15*'Parameters (t)'!$B$103 -> 19.813491 | D15: =$B15*'Parameters (t)'!$C$103 -> 15.136782 | E15: =$B15*'Parameters (t)'!$D$103 -> 66.814104 | F15: =$B15*'Parameters (t)'!$E$103 -> 8.7091879
... A204: 1900 | B204: 912709.28 | C204: =$B204*'Parameters (t)'!$B$103 -> 163694.88 | D204: =$B204*'Parameters (t)'!$C$103 -> 125056.9 | E204: =$B204*'Parameters (t)'!$D$103 -> 552004.02 | F204: =$B204*'Parameters (t)'!$E$103 -> 71953.472
A205: 1901 | B205: 948639.82 | C205: =$B205*'Parameters (t)'!B104 -> 170239.38 | D205: =$B205*'Parameters (t)'!C104 -> 129093.16 | E205: =$B205*'Parameters (t)'!D104 -> 574779.52 | F205: =$B205*'Parameters (t)'!E104 -> 74527.756
A206: 1902 | B206: 987153.98 | C206: =$B206*'Parameters (t)'!B105 -> 177304.44 | D206: =$B206*'Parameters (t)'!C105 -> 133415.19 | E206: =$B206*'Parameters (t)'!D105 -> 599004.47 | F206: =$B206*'Parameters (t)'!E105 -> 77429.883
A207: 1903 | B207: 1027905.6 | C207: =$B207*'Parameters (t)'!B106 -> 184660.4 | D207: =$B207*'Parameters (t)'!C106 -> 137940.85 | E207: =$B207*'Parameters (t)'!D106 -> 624810.88 | F207: =$B207*'Parameters (t)'!E106 -> 80493.518
A208: 1904 | B208: 1067633.4 | C208: =$B208*'Parameters (t)'!B107 -> 191582.74 | D208: =$B208*'Parameters (t)'!C107 -> 142300.55 | E208: =$B208*'Parameters (t)'!D107 -> 650428.42 | F208: =$B208*'Parameters (t)'!E107 -> 83321.706
A209: 1905 | B209: 1114175.9 | C209: =$B209*'Parameters (t)'!B108 -> 200120 | D209: =$B209*'Parameters (t)'!C108 -> 147357.67 | E209: =$B209*'Parameters (t)'!D108 -> 679682.49 | F209: =$B209*'Parameters (t)'!E108 -> 87015.756
A210: 1906 | B210: 1164273.2 | C210: =$B210*'Parameters (t)'!B109 -> 209390.57 | D210: =$B210*'Parameters (t)'!C109 -> 152786.28 | E210: =$B210*'Parameters (t)'!D109 -> 710958.72 | F210: =$B210*'Parameters (t)'!E109 -> 91137.674
A211: 1907 | B211: 1215783.5 | C211: =$B211*'Parameters (t)'!B110 -> 218764.63 | D211: =$B211*'Parameters (t)'!C110 -> 158301.05 | E211: =$B211*'Parameters (t)'!D110 -> 743408.09 | F211: =$B211*'Parameters (t)'!E110 -> 95309.686
A212: 1908 | B212: 1257636.7 | C212: =$B212*'Parameters (t)'!B111 -> 225155.07 | D212: =$B212*'Parameters (t)'!C111 -> 162693.57 | E212: =$B212*'Parameters (t)'!D111 -> 771800.48 | F212: =$B212*'Parameters (t)'!E111 -> 97987.542
A213: 1909 | B213: 1308443.7 | C213: =$B213*'Parameters (t)'!B112 -> 233845.22 | D213: =$B213*'Parameters (t)'!C112 -> 167958.36 | E213: =$B213*'Parameters (t)'!D112 -> 804857.91 | F213: =$B213*'Parameters (t)'!E112 -> 101782.19
A214: 1910 | B214: 1363658 | C214: =$B214*'Parameters (t)'!B113 -> 243427.39 | D214: =$B214*'Parameters (t)'!C113 -> 173684.71 | E214: =$B214*'Parameters (t)'!D113 -> 840501.79 | F214: =$B214*'Parameters (t)'!E113 -> 106044.07
A215: 1911 | B215: 1416706 | C215: =$B215*'Parameters (t)'!B114 -> 252217.83 | D215: =$B215*'Parameters (t)'!C114 -> 179099.34 | E215: =$B215*'Parameters (t)'!D114 -> 875480.56 | F215: =$B215*'Parameters (t)'!E114 -> 109908.26
A216: 1912 | B216: 1476487.8 | C216: =$B216*'Parameters (t)'!B115 -> 262824.05 | D216: =$B216*'Parameters (t)'!C115 -> 185098.22 | E216: =$B216*'Parameters (t)'!D115 -> 913992.47 | F216: =$B216*'Parameters (t)'!E115 -> 114573.01
... A312: 2008 | B312: 25723300 | C312: =$B312*'Parameters (t)'!B211 -> 3169673.9 | D312: =$B312*'Parameters (t)'!C211 -> 4081720.2 | E312: =$B312*'Parameters (t)'!D211 -> 17144493 | F312: =$B312*'Parameters (t)'!E211 -> 1327412.5
A313: 2009
A314: 2010
A315: 2011
A316: 2012
A317: 2013
A318: 2014
A319: 2015
A320: 2016
A321: 2017
A322: 2018
A323: 2019
...

Sheet Parameters (t)
B1: stock splits for 1900-2008 (from Pauliuk 2013)
A2: year | B2: vehicles | C2: machninery | D2: BC | E2: Appliances
A3: 1800
A4: 1801
A5: 1802
A6: 1803
A7: 1804
A8: 1805
A9: 1806
A10: 1807
A11: 1808
A12: 1809
A13: 1810
A14: 1811
... A101: 1898
A102: year | B102: vehicles | C102: machninery | D102: BC | E102: Appliances
A103: 1900 | B103: 0.17935052 | C103: 0.13701723 | D103: 0.60479721 | E103: 0.078835039
A104: 1901 | B104: 0.17945629 | C104: 0.13608238 | D104: 0.60589858 | E104: 0.078562753
A105: 1902 | B105: 0.17961174 | C105: 0.13515134 | D105: 0.60679943 | E105: 0.078437492
A106: 1903 | B106: 0.17964723 | C106: 0.13419602 | D106: 0.60784847 | E106: 0.078308275
A107: 1904 | B107: 0.17944618 | C107: 0.13328596 | D107: 0.60922449 | E107: 0.078043366
A108: 1905 | B108: 0.17961257 | C108: 0.1322571 | D108: 0.61003158 | E108: 0.078098759
A109: 1906 | B109: 0.17984659 | C109: 0.13122889 | D109: 0.61064593 | E109: 0.078278595
A110: 1907 | B110: 0.17993716 | C110: 0.13020497 | D110: 0.61146423 | E110: 0.078393636
A111: 1908 | B111: 0.1790303 | C111: 0.12936453 | D111: 0.61369114 | E111: 0.077914031
A112: 1909 | B112: 0.17872012 | C112: 0.12836499 | D112: 0.61512614 | E112: 0.077788742
A113: 1910 | B113: 0.17851059 | C113: 0.12736677 | D113: 0.61635821 | E113: 0.077764418
A114: 1911 | B114: 0.17803117 | C114: 0.12641955 | D114: 0.61796913 | E114: 0.077580147
... A211: 2008 | B211: 0.1232219 | C211: 0.15867794 | D211: 0.66649665 | E211: 0.051603509
A212: 2009
A213: 2010
A214: 2011
A215: 2012
A216: 2013
A217: 2014
A218: 2015
A219: 2016
A220: 2017
A221: 2018
A222: 2019
...
